Workbook

Sheet Danh sách Test Case
A1: Danh sách Test Case
A6: STT | B6: Module | C6: Test Case ID | D6: Tên Test Case | E6: Điều kiện tiền đề | F6: Bước thực hiện | G6: Dữ liệu test | H6: Kết quả mong đợi | I6: Kết quả thực tế | J6: Trạng thái | K6: Mức độ ưu tiên | L6: Người test | M6: Ngày test
A7: =ROW()-6 -> 1 | B7: Người dùng | C7: ="TC-" & TEXT($A7, "000") -> TC-001 | D7: Đăng ký tài khoản Khách hàng mới thành công | E7: SĐT chưa tồn tại trong hệ thống | F7: 1. Mở App khách > Chọn Đăng ký. 2. Nhập thông tin hợp lệ > Nhấn Tiếp tục. 3. Nhập mã OTP gửi về SMS. | G7: Họ tên: Lương Thị Hồng HươngSĐT: 0377974047Email: a@gmail.comPass: Abc@123OTP: 6 số đúng | H7: Tạo tài khoản thành công (verify='verified'), cấp JWT Token và chuyển vào Trang chủ. | J7: Pass | K7: Cao | L7: Bùi Lương Trọng Trí | M7: 46282
A8: =ROW()-6 -> 2 | B8: Người dùng | C8: ="TC-" & TEXT($A8, "000") -> TC-002 | D8: Đăng ký với SĐT đã kích hoạt trước đó | E8: SĐT đã tồn tại với verify='verified' | F8: 1. Mở App khách > Chọn Đăng ký. 2. Nhập SĐT đã tồn tại > Bấm Tiếp tục. | G8: SĐT: 0394351771 | H8: Hệ thống báo lỗi 409 Conflict ("Số điện thoại đã tồn tại"). Không gửi OTP. | J8: Pass | K8: Cao | L8: Bùi Lương Trọng Trí | M8: 46282
A9: =ROW()-6 -> 3 | B9: Người dùng | C9: ="TC-" & TEXT($A9, "000") -> TC-003 | D9: Đăng ký lại với SĐT đang ở trạng thái unverified | E9: SĐT đã tạo bản ghi tạm (unverified) trước đó | F9: 1. Mở App khách > Đăng ký lại bằng SĐT cũ. 2. Nhập họ tên, mật khẩu mới > Nhấn Tiếp tục. 3. Nhập đúng OTP mới. | G9: SĐT unverified cũHọ tên mớiPass mới | H9: Hệ thống ghi đè thông tin mới, gửi OTP mới; xác thực OTP thành công chuyển verify='verified'. | J9: Pass | K9: Trung bình | L9: Bùi Lương Trọng Trí | M9: 46286
A10: =ROW()-6 -> 4 | B10: Người dùng | C10: ="TC-" & TEXT($A10, "000") -> TC-004 | D10: Nhập sai OTP quá 3 lần liên tiếp khi đăng ký | E10: Đang ở màn hình nhập OTP đăng ký | F10: 1. Nhập sai OTP lần 1 > Bấm Xác nhận. 2. Nhập sai lần 2 > Bấm Xác nhận. 3. Nhập sai lần 3 > Bấm Xác nhận. | G10: OTP: 000000 (sai) | H10: OTP bị hủy (is_expired=TRUE), khóa yêu cầu từ Device/IP 15 phút kèm cảnh báo. | J10: Block | K10: Cao
A11: =ROW()-6 -> 5 | B11: Người dùng | C11: ="TC-" & TEXT($A11, "000") -> TC-005 | D11: Đăng ký với Email sai định dạng RFC 5322 | F11: 1. Mở màn hình đăng ký 2. Nhập email sai định dạng 3. Nhập các trường còn lại hợp lệ 4. Bấm 'Tiếp tục' | G11: Email: abc@@gmail | H11: Hệ thống báo lỗi định dạng Email không hợp lệ | J11: Pass | K11: Cao | L11: Bùi Lương Trọng Trí | M11: 46283
A12: =ROW()-6 -> 6 | B12: Người dùng | C12: ="TC-" & TEXT($A12, "000") -> TC-006 | D12: Đăng ký với SĐT sai định dạng (không đủ 10 số) | F12: 1. Mở màn hình đăng ký 2. Nhập SĐT sai định dạng 3. Nhập các trường còn lại hợp lệ 4. Bấm 'Tiếp tục' | G12: SĐT: 09123456 (8 số) | H12: Hệ thống báo lỗi validate định dạng SĐT, không cho phép submit | J12: Pass | K12: Cao | L12: Bùi Lương Trọng Trí | M12: 46283
A13: =ROW()-6 -> 7 | B13: Người dùng | C13: ="TC-" & TEXT($A13, "000") -> TC-007 | D13: Đăng nhập tài khoản sai mật khẩu quá 5 lần | E13: Tài khoản khách hàng đang active | F13: 1. Nhập đúng SĐT 2. Nhập sai mật khẩu liên tiếp 5 lần 3. Nhấn Đăng nhập. | G13: SĐT: 0394351771Pass: SaiPass123 | H13: Báo lỗi 401; sau lần 5 tạm khóa đăng nhập của SĐT trong 15 phút. | J13: Block | K13: Cao
A14: =ROW()-6 -> 8 | B14: Người dùng | C14: ="TC-" & TEXT($A14, "000") -> TC-008 | D14: Đăng ký với mật khẩu ít hơn 6 ký tự | F14: 1. Mở màn hình đăng ký 2. Nhập mật khẩu < 6 ký tự 3. Bấm 'Tiếp tục | G14: Mật khẩu: Ab@1 | H14: Hệ thống báo lỗi mật khẩu phải từ 6-160 ký tự | J14: Pass | K14: Cao | L14: Bùi Lương Trọng Trí | M14: 46283
A15: =ROW()-6 -> 9 | B15: Người dùng | C15: ="TC-" & TEXT($A15, "000") -> TC-009 | D15: Đăng ký với mật khẩu nhiều hơn 160 ký tự | F15: 1. Mở màn hình đăng ký 2. Nhập mật khẩu > 160 ký tự 3. Bấm 'Tiếp tục' | G15: Mật khẩu gồm 161 ký tự | H15: Hệ thống báo lỗi mật khẩu phải từ 6-160 ký tự | J15: Pass | K15: Cao | L15: Bùi Lương Trọng Trí | M15: 46283
A16: =ROW()-6 -> 10 | B16: Người dùng | C16: ="TC-" & TEXT($A16, "000") -> TC-010 | D16: Đăng ký với mật khẩu thiếu chữ viết hoa | F16: 1. Mở màn hình đăng ký 2. Nhập mật khẩu không có chữ hoa 3. Bấm 'Tiếp tục' | G16: Mật khẩu: abc@123 | H16: Hệ thống báo lỗi mật khẩu phải có ít nhất 1 chữ hoa | J16: Pass | K16: Cao | L16: Bùi Lương Trọng Trí | M16: 46283
A17: =ROW()-6 -> 11 | B17: Người dùng | C17: ="TC-" & TEXT($A17, "000") -> TC-011 | D17: Đăng ký với mật khẩu thiếu chữ số | F17: 1. Mở màn hình đăng ký 2. Nhập mật khẩu không có số 3. Bấm 'Tiếp tục' | G17: Mật khẩu: Abc@xyz | H17: Hệ thống báo lỗi mật khẩu phải có ít nhất 1 chữ số | J17: Pass | K17: Cao | L17: Bùi Lương Trọng Trí | M17: 46283
A18: =ROW()-6 -> 12 | B18: Người dùng | C18: ="TC-" & TEXT($A18, "000") -> TC-012 | D18: Đăng ký với mật khẩu thiếu ký tự đặc biệt | F18: 1. Mở màn hình đăng ký 2. Nhập mật khẩu không có ký tự đặc biệt 3. Bấm 'Tiếp tục' | G18: Mật khẩu: Abc12345 | H18: Hệ thống báo lỗi mật khẩu phải có ít nhất 1 ký tự đặc biệt | J18: Pass | K18: Cao | L18: Bùi Lương Trọng Trí | M18: 46283
A19: =ROW()-6 -> 13 | B19: Người dùng | C19: ="TC-" & TEXT($A19, "000") -> TC-013 | D19: Cơ chế Single Active Session (Đăng nhập thiết bị B đá thiết bị A) | E19: Tài khoản đang đăng nhập hoạt động trên Thiết bị A | F19: 1. Dùng tài khoản đó đăng nhập trên Thiết bị B. 2. Trên Thiết bị A, thực hiện gọi 1 API bất kỳ. | G19: Cùng 1 tài khoản khách hàng | H19: Thiết bị B đăng nhập thành công. Thiết bị A nhận lỗi 401 (SESSION_TERMINATED_BY_ANOTHER_DEVICE), đếm ngược 15s và đẩy về màn Đăng nhập. | J19: Block | K19: Cao
A20: =ROW()-6 -> 14 | B20: Người dùng | C20: ="TC-" & TEXT($A20, "000") -> TC-014 | D20: Nhập mã OTP đã hết hạn (> 3 phút) | E20: OTP đã được sinh quá 3 phút trước | F20: 1. Nhập đúng mã OTP nhưng đã hết hạn 2. Bấm xác nhận | G20: OTP hết hạn (expired_at < NOW()) | H20: Hệ thống báo lỗi mã OTP đã hết hạn | J20: Pass | K20: Cao | L20: Bùi Lương Trọng Trí | M20: 46283
A21: =ROW()-6 -> 15 | B21: Người dùng | C21: ="TC-" & TEXT($A21, "000") -> TC-015 | D21: Bấm 'Gửi lại mã' sau khi đủ 120 giây | E21: Đang ở màn hình OTP, đã quá 120 giây | F21: 1. Bấm nút 'Gửi lại mã' sau 120 giây | H21: OTP cũ bị huỷ (is_expired=TRUE); OTP mới được sinh với hạn 3 phút mới và gửi SMS | J21: Pass | K21: Cao | L21: Bùi Lương Trọng Trí | M21: 46283
A22: =ROW()-6 -> 16 | B22: Người dùng | C22: ="TC-" & TEXT($A22, "000") -> TC-016 | D22: Gửi lại mã OTP vượt quá 3 lần trong 15 phút | E22: Đã gửi lại OTP 3 lần trong vòng 15 phút cho 1 SĐT | F22: 1. Tiếp tục bấm 'Gửi lại mã' lần thứ 4 trong vòng 15 phút | G22: Số lần gửi lại: lần 4 trong 15 phút | H22: Hệ thống trả lỗi 429 Too Many Requests, không gửi thêm OTP | J22: Pass | K22: Trung bình | M22: 46287
A23: =ROW()-6 -> 17 | B23: Người dùng | C23: ="TC-" & TEXT($A23, "000") -> TC-017 | D23: Thoát App khi đang ở màn hình OTP và quay lại đăng ký cùng SĐT trong vòng 3 phút | E23: Đã đăng ký với SĐT X (verify='unverified'), OTP cũ còn hạn (< 3 phút) | F23: 1. Thoát App khi đang ở màn hình nhập OTP 2. Mở lại App, nhập lại cùng SĐT X để đăng ký 3. Bấm 'Tiếp tục' | G23: SĐT X, OTP cũ còn hạn | H23: Backend nhận diện OTP cũ còn hạn, trả cờ OTP_ALREADY_SENT kèm số giây còn lại; Client vào thẳng màn hình OTP với đếm ngược tiếp tục, không gửi SMS mới | I23: Hiện thông báo không thể gửi OTP, không quay lại màn hình nhập OTP | J23: Fail | K23: Trung bình | L23: Bùi Lương Trọng Trí | M23: 46283
A24: =ROW()-6 -> 18 | B24: Người dùng | C24: ="TC-" & TEXT($A24, "000") -> TC-018 | D24: Khôi phục mật khẩu (Quên mật khẩu) qua SMS OTP | E24: Tài khoản khách hàng tồn tại trong hệ thống | F24: 1. Bấm Quên mật khẩu > Nhập SĐT. 2. Nhập đúng OTP nhận được. 3. Nhập mật khẩu mới thỏa điều kiện > Bấm Xác nhận. | G24: SĐT: 0394351771Pass mới: NewPass@2026 | H24: Đổi mật khẩu thành công, toàn bộ session cũ bị revoked (reason='password_changed'), buộc đăng nhập lại bằng mật khẩu mới. | J24: Pass | K24: Cao | L24: Bùi Lương Trọng Trí | M24: 46283
A25: =ROW()-6 -> 19 | B25: Người dùng | C25: ="TC-" & TEXT($A25, "000") -> TC-019 | D25: Đăng nhập thành công với SĐT và mật khẩu đúng | E25: Tài khoản tồn tại, verify='verified', role='customer' | F25: 1. Nhập SĐT và Mật khẩu đúng 2. Bấm 'Đăng nhập' | G25: SĐT: 0394351771; Mật khẩu đúng | H25: Đăng nhập thành công; trả về access_token và refresh_token; tạo users_session mới status='active' | J25: Pass | K25: Cao | L25: Bùi Lương Trọng Trí | M25: 46283
A26: =ROW()-6 -> 20 | B26: Người dùng | C26: ="TC-" & TEXT($A26, "000") -> TC-020 | D26: Đăng nhập với SĐT không tồn tại trong hệ thống | E26: SĐT chưa từng đăng ký | F26: 1. Nhập SĐT không tồn tại và Mật khẩu bất kỳ 2. Bấm 'Đăng nhập' | G26: SĐT: 0999999999 (không tồn tại) | H26: Trả lỗi 401 Unauthorized: 'Số điện thoại hoặc mật khẩu không chính xác' | J26: Pass | K26: Cao | L26: Bùi Lương Trọng Trí | M26: 46283
A27: =ROW()-6 -> 21 | B27: Người dùng | C27: ="TC-" & TEXT($A27, "000") -> TC-021 | D27: Đăng nhập với tài khoản có role khác 'customer' | E27: Tài khoản tồn tại với role='partner' hoặc 'admin' | F27: 1. Nhập SĐT của tài khoản partner/admin và mật khẩu đúng 2. Bấm 'Đăng nhập' (trên App khách hàng) | G27: SĐT partner/admin | H27: Trả lỗi 401 Unauthorized do role != 'customer' | J27: Pass | K27: Cao | L27: Bùi Lương Trọng Trí | M27: 46286
A28: =ROW()-6 -> 22 | B28: Người dùng | C28: ="TC-" & TEXT($A28, "000") -> TC-022 | D28: Đăng nhập khi tài khoản đang bị khoá ('suspended') | E28: Tài khoản tồn tại, verify='suspended' | F28: 1. Nhập SĐT và mật khẩu đúng của tài khoản suspended 2. Bấm 'Đăng nhập' | G28: SĐT tài khoản suspended | H28: Trả lỗi 403 Forbidden: 'Tài khoản đã bị tạm khóa' | J28: Block | K28: Cao
A29: =ROW()-6 -> 23 | B29: Người dùng | C29: ="TC-" & TEXT($A29, "000") -> TC-023 | D29: Đăng nhập sai mật khẩu | E29: Tài khoản tồn tại, verify='verified' | F29: 1. Nhập đúng SĐT, sai mật khẩu 2. Bấm 'Đăng nhập' | G29: Mật khẩu sai | H29: Trả lỗi 401 Unauthorized: 'Sai thông tin đăng nhập' | J29: Pass | K29: Cao | L29: Bùi Lương Trọng Trí | M29: 46286
A30: =ROW()-6 -> 24 | B30: Người dùng | C30: ="TC-" & TEXT($A30, "000") -> TC-024 | D30: Đăng nhập sai mật khẩu 5 lần liên tiếp | E30: Tài khoản tồn tại, verify='verified' | F30: 1. Nhập sai mật khẩu liên tiếp 5 lần | G30: 5 lần nhập sai mật khẩu | H30: Tài khoản tạm khoá đăng nhập trong 15 phút; hiển thị thông báo 'Tài khoản tạm thời bị khóa đăng nhập do nhập sai 5 lần. Vui lòng thử lại sau 15 phút hoặc sử dụng Quên mật khẩu' | J30: Block | K30: Cao
A31: =ROW()-6 -> 25 | B31: Người dùng | C31: ="TC-" & TEXT($A31, "000") -> TC-025 | D31: Đăng nhập lại trong thời gian đang bị tạm khoá do sai mật khẩu | E31: Tài khoản đang bị khoá đăng nhập 15 phút do sai mật khẩu 5 lần | F31: 1. Nhập đúng mật khẩu trong thời gian bị khoá 2. Bấm 'Đăng nhập' | G31: Mật khẩu đúng nhưng đang trong 15 phút khoá | H31: Hệ thống vẫn từ chối đăng nhập và hiển thị thông báo còn thời gian khoá | J31: Block | K31: Trung bình
A32: =ROW()-6 -> 26 | B32: Người dùng | C32: ="TC-" & TEXT($A32, "000") -> TC-026 | D32: Đăng xuất thành công | E32: Khách hàng đã đăng nhập, có session active | F32: 1. Bấm 'Đăng xuất' | H32: Session hiện tại chuyển status='revoked', reason='user_logout'; token trên thiết bị bị vô hiệu hoá; chuyển về màn hình đăng nhập | J32: Pass | K32: Cao | L32: Bùi Lương Trọng Trí | M32: 46283
A33: =ROW()-6 -> 27 | B33: Người dùng | C33: ="TC-" & TEXT($A33, "000") -> TC-027 | D33: Yêu cầu quên mật khẩu với SĐT chưa đăng ký | E33: SĐT không tồn tại trong hệ thống | F33: 1. Bấm 'Quên mật khẩu' 2. Nhập SĐT không tồn tại 3. Bấm xác nhận | G33: SĐT không tồn tại | H33: Hệ thống báo lỗi SĐT không tồn tại, không gửi OTP | J33: Pass | K33: Cao | L33: Bùi Lương Trọng Trí | M33: 46283
A34: =ROW()-6 -> 28 | B34: Người dùng | C34: ="TC-" & TEXT($A34, "000") -> TC-028 | D34: Yêu cầu quên mật khẩu với SĐT hợp lệ đã đăng ký | E34: SĐT tồn tại và đã verified | F34: 1. Bấm 'Quên mật khẩu' 2. Nhập SĐT hợp lệ 3. Bấm xác nhận | G34: SĐT: 0912345678 (đã tồn tại) | H34: Hệ thống sinh OTP SMS 6 số, hạn 3 phút, type='reset_password' và gửi về SĐT | J34: Pass | K34: Cao | L34: Bùi Lương Trọng Trí | M34: 46283
A35: =ROW()-6 -> 29 | B35: Người dùng | C35: ="TC-" & TEXT($A35, "000") -> TC-029 | D35: Cập nhật hồ sơ với Ngày sinh lớn hơn ngày hiện tại | E35: Khách hàng đã đăng nhập | F35: 1. Vào mục Hồ sơ cá nhân. 2. Chọn Ngày sinh trong tương lai. 3. Bấm Lưu thay đổi. | G35: DOB: Ngày mai | H35: Hệ thống chặn không cho chọn ngày tương lai | J35: Pass | K35: Trung bình | L35: Bùi Lương Trọng Trí | M35: 46282
A36: =ROW()-6 -> 30 | B36: Thợ & KYC | C36: ="TC-" & TEXT($A36, "000") -> TC-030 | D36: Thợ nộp hồ sơ đăng ký mới đầy đủ thông tin hợp lệ | E36: SĐT và CCCD chưa từng đăng ký thợ | F36: 1. Mở App thợ > Trở thành thợ FixHub. 2. Nhập thông tin cá nhân, chọn khu vực, kỹ năng. 3. Tải ảnh CCCD 2 mặt (<=5MB). 4. Bấm Gửi hồ sơ. | G36: Họ tên: Trần Văn BSĐT: 0987654321CCCD: 0123456789Ảnh: jpg < 5MB | H36: Hồ sơ được tạo thành công với trạng thái pending, users.verify='unverified'. Ảnh lưu Private Bucket. | J36: Block | K36: Cao
A37: =ROW()-6 -> 31 | B37: Thợ & KYC | C37: ="TC-" & TEXT($A37, "000") -> TC-031 | D37: Nộp hồ sơ thợ với số CCCD đã tồn tại | E37: CCCD đã có trong bảng technician_profile | F37: 1. Điền form đăng ký thợ. 2. Nhập CCCD đã tồn tại trên hệ thống. 3. Bấm Gửi hồ sơ. | G37: CCCD: 0123456789 (đã có) | H37: Báo lỗi 409 Conflict ("Số điện thoại hoặc Số CCCD này đã tồn tại trên hệ thống"). | J37: Block | K37: Cao
A38: =ROW()-6 -> 32 | B38: Thợ & KYC | C38: ="TC-" & TEXT($A38, "000") -> TC-032 | D38: Thợ đăng nhập khi hồ sơ đang chờ duyệt (pending) | E38: Tài khoản thợ có approval_status='pending' | F38: 1. Mở App thợ. 2. Nhập đúng SĐT và mật khẩu. 3. Bấm Đăng nhập. | G38: SĐT thợ đang pending | H38: Chặn đăng nhập, trả về HTTP 403 Forbidden kèm thông báo hồ sơ đang chờ xét duyệt. | J38: Block | K38: Cao
A39: =ROW()-6 -> 33 | B39: Thợ & KYC | C39: ="TC-" & TEXT($A39, "000") -> TC-033 | D39: Admin phê duyệt hồ sơ thợ hợp lệ | E39: Hồ sơ thợ đang ở trạng thái pending | F39: 1. Admin vào Quản lý thợ > Danh sách chờ duyệt. 2. Mở chi tiết đối soát thông tin và ảnh CCCD. 3. Bấm Phê duyệt hồ sơ. | G39: ID hồ sơ hợp lệ | H39: Cập nhật approval_status='approved', users.verify='verified'. Gửi SMS thông báo phê duyệt thành công cho thợ. | J39: Block | K39: Cao
A40: =ROW()-6 -> 34 | B40: Thợ & KYC | C40: ="TC-" & TEXT($A40, "000") -> TC-034 | D40: Admin từ chối hồ sơ thợ kèm lý do | E40: Hồ sơ thợ đang ở trạng thái pending | F40: 1. Mở chi tiết hồ sơ chờ duyệt. 2. Bấm Từ chối. 3. Nhập lý do từ chối > Xác nhận. | G40: Lý do: "Ảnh CCCD mờ, không rõ số" | H40: Cập nhật approval_status='rejected', lưu rejection_reason. Bắn SMS thông báo từ chối kèm lý do cho thợ. | J40: Block | K40: Cao
A41: =ROW()-6 -> 35 | B41: Thợ & KYC | C41: ="TC-" & TEXT($A41, "000") -> TC-035 | D41: Đăng nhập thành công sau khi được Admin duyệt | E41: Thợ đã được Admin duyệt (approved) | F41: 1. Mở App thợ. 2. Nhập đúng SĐT và mật khẩu. 3. Bấm Đăng nhập. | G41: SĐT & Pass thợ approved | H41: Cấp JWT Token thành công và chuyển thẳng vào Màn hình Trang chủ (Home Dashboard). | J41: Block | K41: Cao
A42: =ROW()-6 -> 36 | B42: Tìm kiếm & Điều phối | C42: ="TC-" & TEXT($A42, "000") -> TC-036 | D42: Admin xem danh sách Ticket unassigned ở màn Nhiệm vụ | E42: Có ít nhất 1 ticket ở trạng thái unassigned | F42: 1. Admin vào màn Nhiệm vụ. 2. Chọn nhóm Chưa gán. | G42: Ticket unassigned | H42: Danh sách hiển thị các ticket unassigned với mã đơn, dịch vụ, địa chỉ, giờ hẹn. | J42: Pass | K42: Cao | L42: Bùi Lương Trọng Trí | M42: 46287
A43: =ROW()-6 -> 37 | B43: Tìm kiếm & Điều phối | C43: ="TC-" & TEXT($A43, "000") -> TC-037 | D43: Ticket sau khi gán hiển thị tên thợ | E43: Admin vừa gán ticket cho thợ | F43: 1. Quay lại màn Nhiệm vụ. 2. Kiểm tra đơn. | G43: Ticket assigned | H43: Ticket đã gán kèm tên thợ, technician_id đúng thợ. | J43: Pass | K43: Cao | L43: Bùi Lương Trọng Trí | M43: 46287
A44: =ROW()-6 -> 38 | B44: Tìm kiếm & Điều phối | C44: ="TC-" & TEXT($A44, "000") -> TC-038 | D44: Thợ thấy Ticket mới ở nhiệm vụ mới gần bạn và nhiệm vụ mới ở tab nhiệm vụ | E44: Admin vừa gán ticket cho thợ A | F44: 1. Thợ A mở App thợ > Nhiệm vụ > Nhiệm vụ mới. | G44: Ticket assigned cho thợ A | H44: Ticket xuất hiện trong danh sách nhiệm vụ mới | J44: Pass | K44: Cao | L44: Bùi Lương Trọng Trí | M44: 46287
...

Sheet Danh sách lỗi 
A1: Danh sách lỗi (Fail)
A3: STT | B3: Module | C3: Test Case ID | D3: Tên Test Case | E3: Điều kiện tiền đề | F3: Bước thực hiện | G3: Dữ liệu test | H3: Kết quả mong đợi | I3: Kết quả thực tế | J3: Trạng thái | K3: Mức độ ưu tiên | L3: Người test | M3: Ngày test
A4: =IFERROR(__xludf.DUMMYFUNCTION("FILTER('Danh sách Test Case'!A7:M1000, 'Danh sách Test Case'!J7:J1000=""Fail"")"),17.0) -> 17 | B4: =IFERROR(__xludf.DUMMYFUNCTION("""COMPUTED_VALUE"""),"Người dùng") -> Người dùng | C4: =IFERROR(__xludf.DUMMYFUNCTION("""COMPUTED_VALUE"""),"TC-017") -> TC-017 | D4: =IFERROR(__xludf.DUMMYFUNCTION("""COMPUTED_VALUE"""),"Thoát App khi đang ở màn hình OTP và quay lại đăng ký cùng SĐT trong vòng 3 phút") -> Thoát App khi đang ở màn hình OTP và quay lại đăng ký cùng SĐT trong vòng 3 phút | E4: =IFERROR(__xludf.DUMMYFUNCTION("""COMPUTED_VALUE"""),"Đã đăng ký với SĐT X (verify='unverified'), OTP cũ còn hạn (< 3 phút)") -> Đã đăng ký với SĐT X (verify='unverified'), OTP cũ còn hạn (< 3 phút) | F4: =IFERROR(__xludf.DUMMYFUNCTION("""COMPUTED_VALUE"""),"1. Thoát App khi đang ở màn hình nhập OTP 2. Mở lại App, nhập lại cùng SĐT X để đăng ký 3. Bấm 'Tiếp tục'") -> 1. Thoát App khi đang ở màn hình nhập OTP 2. Mở lại App, nhập lại cùng SĐT X để đăng ký 3. Bấm 'Tiếp tục' | G4: =IFERROR(__xludf.DUMMYFUNCTION("""COMPUTED_VALUE"""),"SĐT X, OTP cũ còn hạn") -> SĐT X, OTP cũ còn hạn | H4: =IFERROR(__xludf.DUMMYFUNCTION("""COMPUTED_VALUE"""),"Backend nhận diện OTP cũ còn hạn, trả cờ OTP_ALREADY_SENT kèm số giây còn lại; Client vào thẳng màn hình OTP với đếm ngược tiếp tục, không gửi SMS mới") -> Backend nhận diện OTP cũ còn hạn, trả cờ OTP_ALREADY_SENT kèm số giây còn lại; Client vào thẳng màn hình OTP với đếm ngược tiếp tục, không gửi SMS mới | I4: =IFERROR(__xludf.DUMMYFUNCTION("""COMPUTED_VALUE"""),"Hiện thông báo không thể gửi OTP, không quay lại màn hình nhập OTP") -> Hiện thông báo không thể gửi OTP, không quay lại màn hình nhập OTP | J4: =IFERROR(__xludf.DUMMYFUNCTION("""COMPUTED_VALUE"""),"Fail") -> Fail | K4: =IFERROR(__xludf.DUMMYFUNCTION("""COMPUTED_VALUE"""),"Trung bình") -> Trung bình | L4: =IFERROR(__xludf.DUMMYFUNCTION("""COMPUTED_VALUE"""),"Bùi Lương Trọng Trí") -> Bùi Lương Trọng Trí | M4: =IFERROR(__xludf.DUMMYFUNCTION("""COMPUTED_VALUE"""),46283.0) -> 46283

Sheet Tổng hợp 
A1: BÁO CÁO TỔNG HỢP KIỂM THỬ
A3: Dự án / Hệ thống: | B3: FixHub
A4: Phạm vi kiểm thử: | B4: Toàn bộ luồng nghiệp vụ (App Khách hàng, App Thợ, Web Admin)
A5: Thời gian kiểm thử: | B5: 17/09/2026 - 23/09/2026
A6: Người tổng hợp: | B6: Bùi Lương Trọng Trí
A7: Ngày lập báo cáo: | B7: 46289
A9: 1. Thống kê theo trạng thái thực thi
A11: Trạng thái | B11: Số lượng | C11: Tỷ lệ (%)
A12: Pass | B12: =COUNTIF('Danh sách Test Case'!$J:$J, A12) -> 158 | C12: =B12/$B$16 -> 0.50803859
A13: Fail | B13: =COUNTIF('Danh sách Test Case'!$J:$J, A13) -> 1 | C13: =B13/$B$16 -> 0.0032154341
A14: Block | B14: =COUNTIF('Danh sách Test Case'!$J:$J, A14) -> 151 | C14: =B14/$B$16 -> 0.48553055
A15: Chưa test | B15: =COUNTIF('Danh sách Test Case'!$J:$J, A15) -> 1 | C15: =B15/$B$16 -> 0.0032154341
A16: Tổng cộng | B16: =SUM(B12:B15) -> 311 | C16: =SUM(C12:C15) -> 1
A18: Tỷ lệ Pass / số đã thực thi (Pass+Fail): | C18: =B12/(B16 - B15 -B14) -> 0.99371069
A21: 2. Thống kê theo mức độ ưu tiên
A23: Mức độ ưu tiên | B23: Số lượng | C23: Tỷ lệ (%)
A24: Cao | B24: =COUNTIF('Danh sách Test Case'!$K:$K,A24) -> 210 | C24: =B24/$B$16 -> 0.67524116
A25: Trung bình | B25: =COUNTIF('Danh sách Test Case'!$K:$K,A25) -> 89 | C25: =B25/$B$16 -> 0.28617363
A26: thấp | B26: =COUNTIF('Danh sách Test Case'!$K:$K,A26) -> 12 | C26: =B26/$B$16 -> 0.038585209
A29: 3. Thống kê theo Module
A31: Module | B31: Pass | C31: Fail | D31: Block | E31: Chưa test | F31: Tổng
A32: Người dùng | B32: =COUNTIFS('Danh sách Test Case'!$B:$B, $A32, 'Danh sách Test Case'!$J:$J, B$31) -> 22 | C32: =COUNTIFS('Danh sách Test Case'!$B:$B, $A32, 'Danh sách Test Case'!$J:$J, C$31) -> 1 | D32: =COUNTIFS('Danh sách Test Case'!$B:$B, $A32, 'Danh sách Test Case'!$J:$J, D$31) -> 6 | E32: =COUNTIFS('Danh sách Test Case'!$B:$B, $A32, 'Danh sách Test Case'!$J:$J, E$31) -> 0 | F32: =SUM($B32:$E32) -> 29
A33: Thợ & KYC | B33: =COUNTIFS('Danh sách Test Case'!$B:$B, $A33, 'Danh sách Test Case'!$J:$J, B$31) -> 0 | C33: =COUNTIFS('Danh sách Test Case'!$B:$B, $A33, 'Danh sách Test Case'!$J:$J, C$31) -> 0 | D33: =COUNTIFS('Danh sách Test Case'!$B:$B, $A33, 'Danh sách Test Case'!$J:$J, D$31) -> 6 | E33: =COUNTIFS('Danh sách Test Case'!$B:$B, $A33, 'Danh sách Test Case'!$J:$J, E$31) -> 0 | F33: =SUM($B33:$E33) -> 6
A34: Tìm kiếm & Điều phối | B34: =COUNTIFS('Danh sách Test Case'!$B:$B, $A34, 'Danh sách Test Case'!$J:$J, B$31) -> 22 | C34: =COUNTIFS('Danh sách Test Case'!$B:$B, $A34, 'Danh sách Test Case'!$J:$J, C$31) -> 0 | D34: =COUNTIFS('Danh sách Test Case'!$B:$B, $A34, 'Danh sách Test Case'!$J:$J, D$31) -> 15 | E34: =COUNTIFS('Danh sách Test Case'!$B:$B, $A34, 'Danh sách Test Case'!$J:$J, E$31) -> 0 | F34: =SUM($B34:$E34) -> 37
A35: Đặt lịch & Đơn hàng | B35: =COUNTIFS('Danh sách Test Case'!$B:$B, $A35, 'Danh sách Test Case'!$J:$J, B$31) -> 31 | C35: =COUNTIFS('Danh sách Test Case'!$B:$B, $A35, 'Danh sách Test Case'!$J:$J, C$31) -> 0 | D35: =COUNTIFS('Danh sách Test Case'!$B:$B, $A35, 'Danh sách Test Case'!$J:$J, D$31) -> 11 | E35: =COUNTIFS('Danh sách Test Case'!$B:$B, $A35, 'Danh sách Test Case'!$J:$J, E$31) -> 0 | F35: =SUM($B35:$E35) -> 42
A36: Phát sinh dịch vụ (OCR) | B36: =COUNTIFS('Danh sách Test Case'!$B:$B, $A36, 'Danh sách Test Case'!$J:$J, B$31) -> 0 | C36: =COUNTIFS('Danh sách Test Case'!$B:$B, $A36, 'Danh sách Test Case'!$J:$J, C$31) -> 0 | D36: =COUNTIFS('Danh sách Test Case'!$B:$B, $A36, 'Danh sách Test Case'!$J:$J, D$31) -> 23 | E36: =COUNTIFS('Danh sách Test Case'!$B:$B, $A36, 'Danh sách Test Case'!$J:$J, E$31) -> 0 | F36: =SUM($B36:$E36) -> 23
A37: Thanh toán & Ví | B37: =COUNTIFS('Danh sách Test Case'!$B:$B, $A37, 'Danh sách Test Case'!$J:$J, B$31) -> 20 | C37: =COUNTIFS('Danh sách Test Case'!$B:$B, $A37, 'Danh sách Test Case'!$J:$J, C$31) -> 0 | D37: =COUNTIFS('Danh sách Test Case'!$B:$B, $A37, 'Danh sách Test Case'!$J:$J, D$31) -> 16 | E37: =COUNTIFS('Danh sách Test Case'!$B:$B, $A37, 'Danh sách Test Case'!$J:$J, E$31) -> 1 | F37: =SUM($B37:$E37) -> 37
A38: Đánh giá & Phản hồi | B38: =COUNTIFS('Danh sách Test Case'!$B:$B, $A38, 'Danh sách Test Case'!$J:$J, B$31) -> 0 | C38: =COUNTIFS('Danh sách Test Case'!$B:$B, $A38, 'Danh sách Test Case'!$J:$J, C$31) -> 0 | D38: =COUNTIFS('Danh sách Test Case'!$B:$B, $A38, 'Danh sách Test Case'!$J:$J, D$31) -> 17 | E38: =COUNTIFS('Danh sách Test Case'!$B:$B, $A38, 'Danh sách Test Case'!$J:$J, E$31) -> 0 | F38: =SUM($B38:$E38) -> 17
A39: Khiếu nại & Bảo hành | B39: =COUNTIFS('Danh sách Test Case'!$B:$B, $A39, 'Danh sách Test Case'!$J:$J, B$31) -> 0 | C39: =COUNTIFS('Danh sách Test Case'!$B:$B, $A39, 'Danh sách Test Case'!$J:$J, C$31) -> 0 | D39: =COUNTIFS('Danh sách Test Case'!$B:$B, $A39, 'Danh sách Test Case'!$J:$J, D$31) -> 16 | E39: =COUNTIFS('Danh sách Test Case'!$B:$B, $A39, 'Danh sách Test Case'!$J:$J, E$31) -> 0 | F39: =SUM($B39:$E39) -> 16
A40: Chat Khách - Thợ | B40: =COUNTIFS('Danh sách Test Case'!$B:$B, $A40, 'Danh sách Test Case'!$J:$J, B$31) -> 0 | C40: =COUNTIFS('Danh sách Test Case'!$B:$B, $A40, 'Danh sách Test Case'!$J:$J, C$31) -> 0 | D40: =COUNTIFS('Danh sách Test Case'!$B:$B, $A40, 'Danh sách Test Case'!$J:$J, D$31) -> 22 | E40: =COUNTIFS('Danh sách Test Case'!$B:$B, $A40, 'Danh sách Test Case'!$J:$J, E$31) -> 0 | F40: =SUM($B40:$E40) -> 22
A41: Quản trị hệ thống | B41: =COUNTIFS('Danh sách Test Case'!$B:$B, $A41, 'Danh sách Test Case'!$J:$J, B$31) -> 63 | C41: =COUNTIFS('Danh sách Test Case'!$B:$B, $A41, 'Danh sách Test Case'!$J:$J, C$31) -> 0 | D41: =COUNTIFS('Danh sách Test Case'!$B:$B, $A41, 'Danh sách Test Case'!$J:$J, D$31) -> 19 | E41: =COUNTIFS('Danh sách Test Case'!$B:$B, $A41, 'Danh sách Test Case'!$J:$J, E$31) -> 0 | F41: =SUM($B41:$E41) -> 82
A42: Tổng cộng | B42: =SUM(Bảng_Thống_kê_theo_Module[Pass]) -> 158 | C42: =SUM(Bảng_Thống_kê_theo_Module[Fail]) -> 1 | D42: =SUM(Bảng_Thống_kê_theo_Module[Block]) -> 151 | E42: =SUM(Bảng_Thống_kê_theo_Module[Chưa test]) -> 1 | F42: =SUM(Bảng_Thống_kê_theo_Module[[#TOTALS],[Pass]:[Chưa test]]) -> 311
